<?xml version="1.0" ?>
<!-- =================================================================================== -->
<!-- |    This document was autogenerated by xacro from ddrive.urdf.xacro              | -->
<!-- |    EDITING THIS FILE BY HAND IS NOT RECOMMENDED                                 | -->
<!-- =================================================================================== -->
<robot name="Diff Drive">
<<<<<<< HEAD
  <gazebo reference="body">
    <material> material Gazebo/TurquoiseGlow </material>
  </gazebo>
  <gazebo reference="right_wheel">
    <material> material Gazebo/LightBlueLaser </material>
  </gazebo>
  <gazebo reference="left_wheel">
    <material>material Gazebo/Bricks </material>
  </gazebo>
  <link name="base">
    <visual>
      <origin rpy="0 0 0" xyz="0 0 0"/>
      <mass value="1"/>
      <geometry>
        <box size=".001 .001 .001"/>
      </geometry>
      <material name="trans_mat">
        <color rgba="0 0 0 0"/>
      </material>
    </visual>
  </link>
  <joint name="fixed" type="fixed">
    <parent link="base"/>
    <child link="body"/>
    <axis xyz="0 0 1"/>
    <origin rpy="0 0 0" xyz="0 0 0"/>
  </joint>
=======
>>>>>>> a123a671f85291762f57a5dd313bdd6118f5bffe
  <link name="body">
    <inertial>
      <origin rpy="0 0 0" xyz="0 0 0"/>
      <mass value="1"/>
      <inertia ixx="1" ixy="1" ixz="1" iyy="1" iyz="1" izz="1"/>
    </inertial>
    <visual>
      <origin rpy="0 0 0" xyz="0 0 0"/>
      <geometry>
<<<<<<< HEAD
        <box size="0.25 0.75 0.25"/>
=======
        <box size="0.25 0.25 0.5"/>
>>>>>>> a123a671f85291762f57a5dd313bdd6118f5bffe
      </geometry>
      <material name="green_mat">
        <color rgba="0 1 0 1"/>
      </material>
    </visual>
    <collision>
      <origin rpy="0 0 0" xyz="0 0 0"/>
      <geometry>
<<<<<<< HEAD
        <box size="0.25 0.75 0.25"/>
=======
        <box size="0.25 0.25 0.5"/>
>>>>>>> a123a671f85291762f57a5dd313bdd6118f5bffe
      </geometry>
    </collision>
  </link>
  <joint name="joint1" type="continuous">
    <parent link="body"/>
    <child link="right_wheel"/>
    <axis xyz="0 0 1"/>
<<<<<<< HEAD
    <origin rpy="0 0 0" xyz="0 0.375 0.125"/>
=======
    <origin rpy="0 0 0" xyz="0 0 0.25"/>
>>>>>>> a123a671f85291762f57a5dd313bdd6118f5bffe
  </joint>
  <link name="right_wheel">
    <visual>
      <inertial>
        <origin rpy="0 0 0" xyz="0 0 0.025"/>
        <mass value="1"/>
        <inertia ixx="1" ixy="1" ixz="1" iyy="1" iyz="1" izz="1"/>
      </inertial>
      <origin rpy="0 0 0" xyz="0 0 0.025"/>
      <geometry>
<<<<<<< HEAD
        <cylinder length="0.05" radius="0.25"/>
=======
        <cylinder length="0.05" radius="0.5"/>
>>>>>>> a123a671f85291762f57a5dd313bdd6118f5bffe
      </geometry>
      <material name="cyan_mat">
        <color rgba="0 1 1 1"/>
      </material>
    </visual>
    <collision>
<<<<<<< HEAD
      <origin rpy="0 0 0" xyz="0 0 0.025"/>
      <geometry>
        <cylinder length="0.05" radius="0.25"/>
=======
      
     origin xyz=&quot;0 0 0.025&quot; rpy=&quot;0 0 0&quot; /&gt;
   
      <geometry>
        <cylinder length="0.05" radius="0.5"/>
>>>>>>> a123a671f85291762f57a5dd313bdd6118f5bffe
      </geometry>
    </collision>
  </link>
  <joint name="joint2" type="continuous">
    <parent link="body"/>
    <child link="left_wheel"/>
    <axis xyz="0 0 1"/>
<<<<<<< HEAD
    <origin rpy="0 0 0" xyz="0 0.375 -0.125"/>
=======
    <origin rpy="0 0 0" xyz="0 0 -0.25"/>
>>>>>>> a123a671f85291762f57a5dd313bdd6118f5bffe
  </joint>
  <link name="left_wheel">
    <visual>
      <inertial>
        <origin rpy="0 0 0" xyz=" 0 0 -0.025"/>
        <mass value="1"/>
        <inertia ixx="1" ixy="1" ixz="1" iyy="1" iyz="1" izz="1"/>
      </inertial>
      <origin rpy="0 0 0" xyz=" 0 0 -0.025"/>
      <geometry>
<<<<<<< HEAD
        <cylinder length="0.05" radius="0.25"/>
=======
        <cylinder length="0.05" radius="0.5"/>
>>>>>>> a123a671f85291762f57a5dd313bdd6118f5bffe
      </geometry>
      <material name="cyan_mat">
        <color rgba="0 1 1 1"/>
      </material>
    </visual>
    <collision>
      <origin rpy="0 0 0" xyz=" 0 0 -0.025"/>
      <geometry>
<<<<<<< HEAD
        <cylinder length="0.05" radius="0.25"/>
=======
        <cylinder length="0.05" radius="0.5"/>
>>>>>>> a123a671f85291762f57a5dd313bdd6118f5bffe
      </geometry>
    </collision>
  </link>
</robot>

