<?xml version = "1.0"?>
<robot name="DiffDrive" xmlns:xacro="http://www.ros.org/wiki/xacro">
<xacro:include filename="ddrive.gazebo.xacro"/> 

<xacro:property name="robot_params" value = "$(find diff_drive)/config/robot_params.yaml" />
<xacro:property name="params" value = '${load_yaml (robot_params)}'/>
<xacro:property name="X" value="${params['base_x']}"/>
<xacro:property name="Y" value="${params['base_y']}"/>
<xacro:property name="Z" value="${params['base_z']}"/>
<xacro:property name="base_m" value="${params['base_mass']}"/>
<xacro:property name="caster_m" value="${params['caster_mass']}"/>
<xacro:property name="r" value="${params['wheel_r']}"/>
<xacro:property name="l" value="${params['wheel_l']}"/>
<xacro:property name="wheel_m" value="${params['wheel_mass']}"/>

<link name="base" />

<link name="body">
    <inertial>
     <origin xyz="0 0 0" rpy="0 0 0"/>
     <mass value="${base_m}"/>
     <inertia ixx="${(base_m*(Y*Y*Z*Z))/12}"  ixy="0"  ixz="0" iyy="${(base_m*(X*X*Z*Z))/12}" iyz="0" izz="${(base_m*(X*X*Y*Y))/12}" />
    </inertial>
  
  <visual>
    <origin xyz="0 0 0" rpy="0 0 0" />
    <geometry>
     <box size="${X} ${Y} ${Z}" />
    </geometry>
    <material name="green_mat">
      <color rgba="0 1 0 1" />
    </material>
  </visual>
  
  <collision>
    <origin xyz="0 0 0" rpy="0 0 0" />
   <geometry>
     <box size="${X} ${Y} ${Z}"/>
   </geometry>
  </collision>
</link>

<link name="right_wheel">
   <inertial>
     <origin xyz="0 0 ${-1*l/2}" rpy="0 0 0"/>
     <mass value="${wheel_m}"/>
     <inertia ixx="${(wheel_m*(3*r*r+l*l))/12}"  ixy="0"  ixz="0" iyy="${(wheel_m*(3*r*r+l*l))/12}" iyz="0" izz="${(wheel_m*r*r)/2}" />
   </inertial>

  <visual>
   <origin xyz="0 0 ${-1*l/2}" rpy="0 0 0"/>
   <geometry>
     <cylinder radius="${r}" length="${l}" />
   </geometry>
     <material name="cyan_mat">
         <color rgba="0 1 1 1" />
     </material>
  </visual>

  <collision>
   <origin xyz="0 0 ${-1*l/2}" rpy="0 0 0"/>
   <geometry>
     <cylinder radius="${r}" length="${l}" />
   </geometry>
  </collision>
</link>

<link name="left_wheel">
   <inertial>
     <origin xyz=" 0 0 ${l/2}" rpy="0 0 0"/>
     <mass value="${wheel_m}"/>
     <inertia ixx="${(wheel_m*(3*r*r+l*l))/12}"  ixy="0"  ixz="0" iyy="${(wheel_m*(3*r*r+l*l))/12}" iyz="0" izz="${(wheel_m*r*r)/2}" />
   </inertial>

  <visual>
   <origin xyz=" 0 0 ${l/2}" rpy="0 0 0"/>
   <geometry>
     <cylinder radius="${r}" length="${l}" />
   </geometry>
     <material name="cyan_mat">
         <color rgba="0 1 1 1" />
     </material>
  </visual>

  <collision>
     <origin xyz=" 0 0 ${l/2}" rpy="0 0 0"/>
   <geometry>
    <cylinder radius="${r}" length="${l}" />
   </geometry>
  </collision>
</link>


<link name="caster">
   <inertial>
     <origin xyz=" 0 0 0" rpy="0 0 0"/>
     <mass value="${caster_m}"/>
     <inertia ixx="${(caster_m*(3*Z*Z+l*l))/12}"  ixy="0"  ixz="0" iyy="${(caster_m*(3*Z*Z+l*l))/12}" iyz="0" izz="${(caster_m*Z*Z)/2}" />
   </inertial>

  <visual>
   <origin xyz=" 0 0 0" rpy="0 0 0"/>
   <geometry>
     <cylinder radius="${Z}" length="${l}" />
   </geometry>
     <material name="cyan_mat">
         <color rgba="0 1 1 1" />
     </material>
  </visual>

  <collision>
     <origin xyz=" 0 0 0" rpy="0 0 0"/>
   <geometry>
    <cylinder radius="${Z}" length="${l}" />
   </geometry>
  </collision>
</link>

<joint name="fixed" type="fixed">
  <parent link="base" />
  <child link="body" />
  <origin xyz="0 0 0" rpy="0 0 0" />  
</joint>

<joint name="joint1" type="continuous">
  <parent link="body" />
  <child link="right_wheel" />
  <axis xyz = "0 0 1" />
  <origin xyz="${X/2} ${Y/2} 0" rpy="0 -1.57 0" />  
</joint>

<joint name="joint2" type="continuous">
  <parent link="body" />
  <child link="left_wheel" />
  <axis xyz = "0 0 1" />
  <origin xyz="${-1*X/2} ${Y/2} 0" rpy="0 -1.57 0" />  
</joint> -->

<joint name="joint3" type="fixed">
  <parent link="body" />
  <child link="caster" />
  <origin xyz="0 ${-1*Y/2} 0" rpy="0 -1.57 0" />  
</joint>

</robot>