<?xml version="1.0" ?>
<!-- =================================================================================== -->
<!-- |    This document was autogenerated by xacro from ddrive.urdf.xacro              | -->
<!-- |    EDITING THIS FILE BY HAND IS NOT RECOMMENDED                                 | -->
<!-- =================================================================================== -->
<robot name="Diff Drive">
  <gazebo reference="body">
    <material> material Gazebo/YellowGlow </material>
  </gazebo>
  <gazebo reference="right_wheel">
    <material> material Gazebo/Indigo </material>
  </gazebo>
  <gazebo reference="left_wheel">
    <material> material Gazebo/Indigo </material>
  </gazebo>
  <gazebo reference="caster">
    <material> material Gazebo/Indigo </material>
  </gazebo>
  <link name="base"/>
  <joint name="fixed" type="fixed">
    <parent link="base"/>
    <child link="body"/>
    <axis xyz="0 1 0"/>
    <origin rpy="0 0 0" xyz="0 0 0"/>
  </joint>
  <link name="body">
    <inertial>
      <origin rpy="0 0 0" xyz="0 0 0"/>
      <mass value="1"/>
      <inertia ixx="1" ixy="1" ixz="1" iyy="1" iyz="1" izz="1"/>
    </inertial>
    <visual>
      <origin rpy="0 0 0" xyz="0 0 0"/>
      <geometry>
        <box size="0.5 0.75 0.125"/>
      </geometry>
      <material name="green_mat">
        <color rgba="0 1 0 1"/>
      </material>
    </visual>
    <collision>
      <origin rpy="0 0 0" xyz="0 0 0"/>
      <geometry>
        <box size="0.5 0.75 0.125"/>
      </geometry>
    </collision>
  </link>
  <joint name="joint1" type="continuous">
    <parent link="body"/>
    <child link="right_wheel"/>
    <axis xyz="0 0 1"/>
    <origin rpy="0 -1.57 0" xyz="0.25 0.375 0"/>
  </joint>
  <link name="right_wheel">
    <visual>
      <inertial>
        <origin rpy="0 0 0" xyz="0 0 -0.05"/>
        <mass value="1"/>
        <inertia ixx="1" ixy="1" ixz="1" iyy="1" iyz="1" izz="1"/>
      </inertial>
      <origin rpy="0 0 0" xyz="0 0 -0.05"/>
      <geometry>
        <cylinder length="0.05" radius="0.25"/>
      </geometry>
      <material name="cyan_mat">
        <color rgba="0 1 1 1"/>
      </material>
    </visual>
    <collision>
      <origin rpy="0 0 0" xyz="0 0 -0.05"/>
      <geometry>
        <cylinder length="0.05" radius="0.25"/>
      </geometry>
    </collision>
  </link>
  <joint name="joint2" type="continuous">
    <parent link="body"/>
    <child link="left_wheel"/>
    <axis xyz="0 0 1"/>
    <origin rpy="0 -1.57 0" xyz="-0.25 0.375 0"/>
  </joint>
  <link name="left_wheel">
    <visual>
      <inertial>
        <origin rpy="0 0 0" xyz=" 0 0 0.025"/>
        <mass value="1"/>
        <inertia ixx="1" ixy="1" ixz="1" iyy="1" iyz="1" izz="1"/>
      </inertial>
      <origin rpy="0 0 0" xyz=" 0 0 0.025"/>
      <geometry>
        <cylinder length="0.05" radius="0.25"/>
      </geometry>
      <material name="cyan_mat">
        <color rgba="0 1 1 1"/>
      </material>
    </visual>
    <collision>
      <origin rpy="0 0 0" xyz=" 0 0 0.025"/>
      <geometry>
        <cylinder length="0.05" radius="0.25"/>
      </geometry>
    </collision>
  </link>
  <joint name="joint3" type="fixed">
    <parent link="body"/>
    <child link="caster"/>
    <axis xyz="0 0 1"/>
    <origin rpy="0 -1.57 0" xyz="0 -0.375 0"/>
  </joint>
  <link name="caster">
    <visual>
      <inertial>
        <origin rpy="0 0 0" xyz=" 0 0 0"/>
        <mass value="1"/>
        <inertia ixx="1" ixy="1" ixz="1" iyy="1" iyz="1" izz="1"/>
      </inertial>
      <origin rpy="0 0 0" xyz=" 0 0 0"/>
      <geometry>
        <cylinder length="0.05" radius="0.125"/>
      </geometry>
      <material name="cyan_mat">
        <color rgba="0 1 1 1"/>
      </material>
    </visual>
    <collision>
      <origin rpy="0 0 0" xyz=" 0 0 0"/>
      <geometry>
        <cylinder length="0.05" radius="0.25"/>
      </geometry>
    </collision>
  </link>
</robot>

